[Wed Jun 08 16:43:21.553149 2016] [wsgi:error] [pid 929] [client 192.168.0.6:55456] mod_wsgi (pid=929): Target WSGI script '/Users/jinho/Citadel/citadel.wsgi' cannot be loaded as Python module.
[Wed Jun 08 16:43:21.553370 2016] [wsgi:error] [pid 929] [client 192.168.0.6:55456] mod_wsgi (pid=929): Exception occurred processing WSGI script '/Users/jinho/Citadel/citadel.wsgi'.
[Wed Jun 08 16:43:21.553413 2016] [wsgi:error] [pid 929] [client 192.168.0.6:55456] Traceback (most recent call last):
[Wed Jun 08 16:43:21.553450 2016] [wsgi:error] [pid 929] [client 192.168.0.6:55456]   File "/Users/jinho/Citadel/citadel.wsgi", line 4, in <module>
[Wed Jun 08 16:43:21.553567 2016] [wsgi:error] [pid 929] [client 192.168.0.6:55456]     execfile(activate_this, dict(__file__=activate_this))
[Wed Jun 08 16:43:21.553608 2016] [wsgi:error] [pid 929] [client 192.168.0.6:55456] IOError: [Errno 2] No such file or directory: '/Users/jinho/CitadelProject/venv/bin/activate_this.py'
[Wed Jun 08 16:44:24.498931 2016] [wsgi:error] [pid 946] [client 192.168.0.6:55486] mod_wsgi (pid=946): Exception occurred processing WSGI script '/Users/jinho/Citadel/citadel.wsgi'., referer: http://192.168.0.6:505/update_post/10
[Wed Jun 08 16:44:24.505153 2016] [wsgi:error] [pid 946] [client 192.168.0.6:55486] Traceback (most recent call last):, referer: http://192.168.0.6:505/update_post/10
[Wed Jun 08 16:44:24.505234 2016] [wsgi:error] [pid 946] [client 192.168.0.6:55486]   File "/Users/jinho/Citadel/venv/lib/python2.7/site-packages/flask/app.py", line 1836, in __call__, referer: http://192.168.0.6:505/update_post/10
[Wed Jun 08 16:44:24.537113 2016] [wsgi:error] [pid 946] [client 192.168.0.6:55486]     return self.wsgi_app(environ, start_response), referer: http://192.168.0.6:505/update_post/10
[Wed Jun 08 16:44:24.537166 2016] [wsgi:error] [pid 946] [client 192.168.0.6:55486]   File "/Users/jinho/Citadel/venv/lib/python2.7/site-packages/flask/app.py", line 1820, in wsgi_app, referer: http://192.168.0.6:505/update_post/10
[Wed Jun 08 16:44:24.537225 2016] [wsgi:error] [pid 946] [client 192.168.0.6:55486]     response = self.make_response(self.handle_exception(e)), referer: http://192.168.0.6:505/update_post/10
[Wed Jun 08 16:44:24.537244 2016] [wsgi:error] [pid 946] [client 192.168.0.6:55486]   File "/Users/jinho/Citadel/venv/lib/python2.7/site-packages/flask/app.py", line 1403, in handle_exception, referer: http://192.168.0.6:505/update_post/10
[Wed Jun 08 16:44:24.537272 2016] [wsgi:error] [pid 946] [client 192.168.0.6:55486]     reraise(exc_type, exc_value, tb), referer: http://192.168.0.6:505/update_post/10
[Wed Jun 08 16:44:24.537286 2016] [wsgi:error] [pid 946] [client 192.168.0.6:55486]   File "/Users/jinho/Citadel/venv/lib/python2.7/site-packages/flask/app.py", line 1817, in wsgi_app, referer: http://192.168.0.6:505/update_post/10
[Wed Jun 08 16:44:24.537310 2016] [wsgi:error] [pid 946] [client 192.168.0.6:55486]     response = self.full_dispatch_request(), referer: http://192.168.0.6:505/update_post/10
[Wed Jun 08 16:44:24.537325 2016] [wsgi:error] [pid 946] [client 192.168.0.6:55486]   File "/Users/jinho/Citadel/venv/lib/python2.7/site-packages/flask/app.py", line 1477, in full_dispatch_request, referer: http://192.168.0.6:505/update_post/10
[Wed Jun 08 16:44:24.537348 2016] [wsgi:error] [pid 946] [client 192.168.0.6:55486]     rv = self.handle_user_exception(e), referer: http://192.168.0.6:505/update_post/10
[Wed Jun 08 16:44:24.537362 2016] [wsgi:error] [pid 946] [client 192.168.0.6:55486]   File "/Users/jinho/Citadel/venv/lib/python2.7/site-packages/flask/app.py", line 1381, in handle_user_exception, referer: http://192.168.0.6:505/update_post/10
[Wed Jun 08 16:44:24.537385 2016] [wsgi:error] [pid 946] [client 192.168.0.6:55486]     reraise(exc_type, exc_value, tb), referer: http://192.168.0.6:505/update_post/10
[Wed Jun 08 16:44:24.537398 2016] [wsgi:error] [pid 946] [client 192.168.0.6:55486]   File "/Users/jinho/Citadel/venv/lib/python2.7/site-packages/flask/app.py", line 1475, in full_dispatch_request, referer: http://192.168.0.6:505/update_post/10
[Wed Jun 08 16:44:24.537446 2016] [wsgi:error] [pid 946] [client 192.168.0.6:55486]     rv = self.dispatch_request(), referer: http://192.168.0.6:505/update_post/10
[Wed Jun 08 16:44:24.537463 2016] [wsgi:error] [pid 946] [client 192.168.0.6:55486]   File "/Users/jinho/Citadel/venv/lib/python2.7/site-packages/flask/app.py", line 1461, in dispatch_request, referer: http://192.168.0.6:505/update_post/10
[Wed Jun 08 16:44:24.537487 2016] [wsgi:error] [pid 946] [client 192.168.0.6:55486]     return self.view_functions[rule.endpoint](**req.view_args), referer: http://192.168.0.6:505/update_post/10
[Wed Jun 08 16:44:24.537502 2016] [wsgi:error] [pid 946] [client 192.168.0.6:55486]   File "/Users/jinho/Citadel/main.py", line 184, in update_post, referer: http://192.168.0.6:505/update_post/10
[Wed Jun 08 16:44:24.537689 2016] [wsgi:error] [pid 946] [client 192.168.0.6:55486]     dbs.commit(), referer: http://192.168.0.6:505/update_post/10
[Wed Jun 08 16:44:24.537710 2016] [wsgi:error] [pid 946] [client 192.168.0.6:55486]   File "/Users/jinho/Citadel/venv/lib/python2.7/site-packages/sqlalchemy/orm/session.py", line 801, in commit, referer: http://192.168.0.6:505/update_post/10
[Wed Jun 08 16:44:24.541024 2016] [wsgi:error] [pid 946] [client 192.168.0.6:55486]     self.transaction.commit(), referer: http://192.168.0.6:505/update_post/10
[Wed Jun 08 16:44:24.541074 2016] [wsgi:error] [pid 946] [client 192.168.0.6:55486]   File "/Users/jinho/Citadel/venv/lib/python2.7/site-packages/sqlalchemy/orm/session.py", line 392, in commit, referer: http://192.168.0.6:505/update_post/10
[Wed Jun 08 16:44:24.541134 2016] [wsgi:error] [pid 946] [client 192.168.0.6:55486]     self._prepare_impl(), referer: http://192.168.0.6:505/update_post/10
[Wed Jun 08 16:44:24.541152 2016] [wsgi:error] [pid 946] [client 192.168.0.6:55486]   File "/Users/jinho/Citadel/venv/lib/python2.7/site-packages/sqlalchemy/orm/session.py", line 372, in _prepare_impl, referer: http://192.168.0.6:505/update_post/10
[Wed Jun 08 16:44:24.541180 2016] [wsgi:error] [pid 946] [client 192.168.0.6:55486]     self.session.flush(), referer: http://192.168.0.6:505/update_post/10
[Wed Jun 08 16:44:24.541195 2016] [wsgi:error] [pid 946] [client 192.168.0.6:55486]   File "/Users/jinho/Citadel/venv/lib/python2.7/site-packages/sqlalchemy/orm/session.py", line 2019, in flush, referer: http://192.168.0.6:505/update_post/10
[Wed Jun 08 16:44:24.541219 2016] [wsgi:error] [pid 946] [client 192.168.0.6:55486]     self._flush(objects), referer: http://192.168.0.6:505/update_post/10
[Wed Jun 08 16:44:24.541233 2016] [wsgi:error] [pid 946] [client 192.168.0.6:55486]   File "/Users/jinho/Citadel/venv/lib/python2.7/site-packages/sqlalchemy/orm/session.py", line 2137, in _flush, referer: http://192.168.0.6:505/update_post/10
[Wed Jun 08 16:44:24.541256 2016] [wsgi:error] [pid 946] [client 192.168.0.6:55486]     transaction.rollback(_capture_exception=True), referer: http://192.168.0.6:505/update_post/10
[Wed Jun 08 16:44:24.541271 2016] [wsgi:error] [pid 946] [client 192.168.0.6:55486]   File "/Users/jinho/Citadel/venv/lib/python2.7/site-packages/sqlalchemy/util/langhelpers.py", line 60, in __exit__, referer: http://192.168.0.6:505/update_post/10
[Wed Jun 08 16:44:24.543352 2016] [wsgi:error] [pid 946] [client 192.168.0.6:55486]     compat.reraise(exc_type, exc_value, exc_tb), referer: http://192.168.0.6:505/update_post/10
[Wed Jun 08 16:44:24.543403 2016] [wsgi:error] [pid 946] [client 192.168.0.6:55486]   File "/Users/jinho/Citadel/venv/lib/python2.7/site-packages/sqlalchemy/orm/session.py", line 2101, in _flush, referer: http://192.168.0.6:505/update_post/10
[Wed Jun 08 16:44:24.543464 2016] [wsgi:error] [pid 946] [client 192.168.0.6:55486]     flush_context.execute(), referer: http://192.168.0.6:505/update_post/10
[Wed Jun 08 16:44:24.543484 2016] [wsgi:error] [pid 946] [client 192.168.0.6:55486]   File "/Users/jinho/Citadel/venv/lib/python2.7/site-packages/sqlalchemy/orm/unitofwork.py", line 373, in execute, referer: http://192.168.0.6:505/update_post/10
[Wed Jun 08 16:44:24.544530 2016] [wsgi:error] [pid 946] [client 192.168.0.6:55486]     rec.execute(self), referer: http://192.168.0.6:505/update_post/10
[Wed Jun 08 16:44:24.544595 2016] [wsgi:error] [pid 946] [client 192.168.0.6:55486]   File "/Users/jinho/Citadel/venv/lib/python2.7/site-packages/sqlalchemy/orm/unitofwork.py", line 532, in execute, referer: http://192.168.0.6:505/update_post/10
[Wed Jun 08 16:44:24.544654 2016] [wsgi:error] [pid 946] [client 192.168.0.6:55486]     uow, referer: http://192.168.0.6:505/update_post/10
[Wed Jun 08 16:44:24.544673 2016] [wsgi:error] [pid 946] [client 192.168.0.6:55486]   File "/Users/jinho/Citadel/venv/lib/python2.7/site-packages/sqlalchemy/orm/persistence.py", line 170, in save_obj, referer: http://192.168.0.6:505/update_post/10
[Wed Jun 08 16:44:24.547093 2016] [wsgi:error] [pid 946] [client 192.168.0.6:55486]     mapper, table, update), referer: http://192.168.0.6:505/update_post/10
[Wed Jun 08 16:44:24.547146 2016] [wsgi:error] [pid 946] [client 192.168.0.6:55486]   File "/Users/jinho/Citadel/venv/lib/python2.7/site-packages/sqlalchemy/orm/persistence.py", line 706, in _emit_update_statements, referer: http://192.168.0.6:505/update_post/10
[Wed Jun 08 16:44:24.547206 2016] [wsgi:error] [pid 946] [client 192.168.0.6:55486]     execute(statement, multiparams), referer: http://192.168.0.6:505/update_post/10
[Wed Jun 08 16:44:24.547225 2016] [wsgi:error] [pid 946] [client 192.168.0.6:55486]   File "/Users/jinho/Citadel/venv/lib/python2.7/site-packages/sqlalchemy/engine/base.py", line 914, in execute, referer: http://192.168.0.6:505/update_post/10
[Wed Jun 08 16:44:24.549944 2016] [wsgi:error] [pid 946] [client 192.168.0.6:55486]     return meth(self, multiparams, params), referer: http://192.168.0.6:505/update_post/10
[Wed Jun 08 16:44:24.549995 2016] [wsgi:error] [pid 946] [client 192.168.0.6:55486]   File "/Users/jinho/Citadel/venv/lib/python2.7/site-packages/sqlalchemy/sql/elements.py", line 323, in _execute_on_connection, referer: http://192.168.0.6:505/update_post/10
[Wed Jun 08 16:44:24.553932 2016] [wsgi:error] [pid 946] [client 192.168.0.6:55486]     return connection._execute_clauseelement(self, multiparams, params), referer: http://192.168.0.6:505/update_post/10
[Wed Jun 08 16:44:24.553985 2016] [wsgi:error] [pid 946] [client 192.168.0.6:55486]   File "/Users/jinho/Citadel/venv/lib/python2.7/site-packages/sqlalchemy/engine/base.py", line 1010, in _execute_clauseelement, referer: http://192.168.0.6:505/update_post/10
[Wed Jun 08 16:44:24.554047 2016] [wsgi:error] [pid 946] [client 192.168.0.6:55486]     compiled_sql, distilled_params, referer: http://192.168.0.6:505/update_post/10
[Wed Jun 08 16:44:24.554066 2016] [wsgi:error] [pid 946] [client 192.168.0.6:55486]   File "/Users/jinho/Citadel/venv/lib/python2.7/site-packages/sqlalchemy/engine/base.py", line 1146, in _execute_context, referer: http://192.168.0.6:505/update_post/10
[Wed Jun 08 16:44:24.554094 2016] [wsgi:error] [pid 946] [client 192.168.0.6:55486]     context), referer: http://192.168.0.6:505/update_post/10
[Wed Jun 08 16:44:24.554108 2016] [wsgi:error] [pid 946] [client 192.168.0.6:55486]   File "/Users/jinho/Citadel/venv/lib/python2.7/site-packages/sqlalchemy/engine/base.py", line 1341, in _handle_dbapi_exception, referer: http://192.168.0.6:505/update_post/10
[Wed Jun 08 16:44:24.554133 2016] [wsgi:error] [pid 946] [client 192.168.0.6:55486]     exc_info, referer: http://192.168.0.6:505/update_post/10
[Wed Jun 08 16:44:24.554147 2016] [wsgi:error] [pid 946] [client 192.168.0.6:55486]   File "/Users/jinho/Citadel/venv/lib/python2.7/site-packages/sqlalchemy/util/compat.py", line 202, in raise_from_cause, referer: http://192.168.0.6:505/update_post/10
[Wed Jun 08 16:44:24.554782 2016] [wsgi:error] [pid 946] [client 192.168.0.6:55486]     reraise(type(exception), exception, tb=exc_tb, cause=cause), referer: http://192.168.0.6:505/update_post/10
[Wed Jun 08 16:44:24.554851 2016] [wsgi:error] [pid 946] [client 192.168.0.6:55486]   File "/Users/jinho/Citadel/venv/lib/python2.7/site-packages/sqlalchemy/engine/base.py", line 1139, in _execute_context, referer: http://192.168.0.6:505/update_post/10
[Wed Jun 08 16:44:24.554933 2016] [wsgi:error] [pid 946] [client 192.168.0.6:55486]     context), referer: http://192.168.0.6:505/update_post/10
[Wed Jun 08 16:44:24.554955 2016] [wsgi:error] [pid 946] [client 192.168.0.6:55486]   File "/Users/jinho/Citadel/venv/lib/python2.7/site-packages/sqlalchemy/engine/default.py", line 450, in do_execute, referer: http://192.168.0.6:505/update_post/10
[Wed Jun 08 16:44:24.556742 2016] [wsgi:error] [pid 946] [client 192.168.0.6:55486]     cursor.execute(statement, parameters), referer: http://192.168.0.6:505/update_post/10
[Wed Jun 08 16:44:24.556876 2016] [wsgi:error] [pid 946] [client 192.168.0.6:55486] OperationalError: (sqlite3.OperationalError) unable to open database file [SQL: u'UPDATE message SET title=? WHERE message.id = ?'] [parameters: (u'4$\\uc544\\uc624 \\uc9c4\\uc9dc \\uc9dc\\uc99d\\ub098\\ub290\\uad6c\\ub9cc', 10)], referer: http://192.168.0.6:505/update_post/10
[Wed Jun 08 16:47:31.626783 2016] [wsgi:error] [pid 946] [client 192.168.0.6:55599] mod_wsgi (pid=946): Exception occurred processing WSGI script '/Users/jinho/Citadel/citadel.wsgi'., referer: http://192.168.0.6:505/
[Wed Jun 08 16:47:31.626888 2016] [wsgi:error] [pid 946] [client 192.168.0.6:55599] Traceback (most recent call last):, referer: http://192.168.0.6:505/
[Wed Jun 08 16:47:31.626904 2016] [wsgi:error] [pid 946] [client 192.168.0.6:55599]   File "/Users/jinho/Citadel/venv/lib/python2.7/site-packages/flask/app.py", line 1836, in __call__, referer: http://192.168.0.6:505/
[Wed Jun 08 16:47:31.626938 2016] [wsgi:error] [pid 946] [client 192.168.0.6:55599]     return self.wsgi_app(environ, start_response), referer: http://192.168.0.6:505/
[Wed Jun 08 16:47:31.626947 2016] [wsgi:error] [pid 946] [client 192.168.0.6:55599]   File "/Users/jinho/Citadel/venv/lib/python2.7/site-packages/flask/app.py", line 1820, in wsgi_app, referer: http://192.168.0.6:505/
[Wed Jun 08 16:47:31.626965 2016] [wsgi:error] [pid 946] [client 192.168.0.6:55599]     response = self.make_response(self.handle_exception(e)), referer: http://192.168.0.6:505/
[Wed Jun 08 16:47:31.626973 2016] [wsgi:error] [pid 946] [client 192.168.0.6:55599]   File "/Users/jinho/Citadel/venv/lib/python2.7/site-packages/flask/app.py", line 1403, in handle_exception, referer: http://192.168.0.6:505/
[Wed Jun 08 16:47:31.626987 2016] [wsgi:error] [pid 946] [client 192.168.0.6:55599]     reraise(exc_type, exc_value, tb), referer: http://192.168.0.6:505/
[Wed Jun 08 16:47:31.626994 2016] [wsgi:error] [pid 946] [client 192.168.0.6:55599]   File "/Users/jinho/Citadel/venv/lib/python2.7/site-packages/flask/app.py", line 1817, in wsgi_app, referer: http://192.168.0.6:505/
[Wed Jun 08 16:47:31.627007 2016] [wsgi:error] [pid 946] [client 192.168.0.6:55599]     response = self.full_dispatch_request(), referer: http://192.168.0.6:505/
[Wed Jun 08 16:47:31.627014 2016] [wsgi:error] [pid 946] [client 192.168.0.6:55599]   File "/Users/jinho/Citadel/venv/lib/python2.7/site-packages/flask/app.py", line 1477, in full_dispatch_request, referer: http://192.168.0.6:505/
[Wed Jun 08 16:47:31.627026 2016] [wsgi:error] [pid 946] [client 192.168.0.6:55599]     rv = self.handle_user_exception(e), referer: http://192.168.0.6:505/
[Wed Jun 08 16:47:31.627032 2016] [wsgi:error] [pid 946] [client 192.168.0.6:55599]   File "/Users/jinho/Citadel/venv/lib/python2.7/site-packages/flask/app.py", line 1381, in handle_user_exception, referer: http://192.168.0.6:505/
[Wed Jun 08 16:47:31.627046 2016] [wsgi:error] [pid 946] [client 192.168.0.6:55599]     reraise(exc_type, exc_value, tb), referer: http://192.168.0.6:505/
[Wed Jun 08 16:47:31.627053 2016] [wsgi:error] [pid 946] [client 192.168.0.6:55599]   File "/Users/jinho/Citadel/venv/lib/python2.7/site-packages/flask/app.py", line 1475, in full_dispatch_request, referer: http://192.168.0.6:505/
[Wed Jun 08 16:47:31.627065 2016] [wsgi:error] [pid 946] [client 192.168.0.6:55599]     rv = self.dispatch_request(), referer: http://192.168.0.6:505/
[Wed Jun 08 16:47:31.627072 2016] [wsgi:error] [pid 946] [client 192.168.0.6:55599]   File "/Users/jinho/Citadel/venv/lib/python2.7/site-packages/flask/app.py", line 1461, in dispatch_request, referer: http://192.168.0.6:505/
[Wed Jun 08 16:47:31.627107 2016] [wsgi:error] [pid 946] [client 192.168.0.6:55599]     return self.view_functions[rule.endpoint](**req.view_args), referer: http://192.168.0.6:505/
[Wed Jun 08 16:47:31.627117 2016] [wsgi:error] [pid 946] [client 192.168.0.6:55599]   File "/Users/jinho/Citadel/main.py", line 201, in show_post, referer: http://192.168.0.6:505/
[Wed Jun 08 16:47:31.627133 2016] [wsgi:error] [pid 946] [client 192.168.0.6:55599]     if q.count() == 0:, referer: http://192.168.0.6:505/
[Wed Jun 08 16:47:31.627141 2016] [wsgi:error] [pid 946] [client 192.168.0.6:55599]   File "/Users/jinho/Citadel/venv/lib/python2.7/site-packages/sqlalchemy/orm/query.py", line 2980, in count, referer: http://192.168.0.6:505/
[Wed Jun 08 16:47:31.638343 2016] [wsgi:error] [pid 946] [client 192.168.0.6:55599]     return self.from_self(col).scalar(), referer: http://192.168.0.6:505/
[Wed Jun 08 16:47:31.638395 2016] [wsgi:error] [pid 946] [client 192.168.0.6:55599]   File "/Users/jinho/Citadel/venv/lib/python2.7/site-packages/sqlalchemy/orm/query.py", line 2749, in scalar, referer: http://192.168.0.6:505/
[Wed Jun 08 16:47:31.638455 2016] [wsgi:error] [pid 946] [client 192.168.0.6:55599]     ret = self.one(), referer: http://192.168.0.6:505/
[Wed Jun 08 16:47:31.638473 2016] [wsgi:error] [pid 946] [client 192.168.0.6:55599]   File "/Users/jinho/Citadel/venv/lib/python2.7/site-packages/sqlalchemy/orm/query.py", line 2718, in one, referer: http://192.168.0.6:505/
[Wed Jun 08 16:47:31.638501 2016] [wsgi:error] [pid 946] [client 192.168.0.6:55599]     ret = list(self), referer: http://192.168.0.6:505/
[Wed Jun 08 16:47:31.638515 2016] [wsgi:error] [pid 946] [client 192.168.0.6:55599]   File "/Users/jinho/Citadel/venv/lib/python2.7/site-packages/sqlalchemy/orm/query.py", line 2761, in __iter__, referer: http://192.168.0.6:505/
[Wed Jun 08 16:47:31.638539 2016] [wsgi:error] [pid 946] [client 192.168.0.6:55599]     return self._execute_and_instances(context), referer: http://192.168.0.6:505/
[Wed Jun 08 16:47:31.638553 2016] [wsgi:error] [pid 946] [client 192.168.0.6:55599]   File "/Users/jinho/Citadel/venv/lib/python2.7/site-packages/sqlalchemy/orm/query.py", line 2774, in _execute_and_instances, referer: http://192.168.0.6:505/
[Wed Jun 08 16:47:31.638577 2016] [wsgi:error] [pid 946] [client 192.168.0.6:55599]     close_with_result=True), referer: http://192.168.0.6:505/
[Wed Jun 08 16:47:31.638590 2016] [wsgi:error] [pid 946] [client 192.168.0.6:55599]   File "/Users/jinho/Citadel/venv/lib/python2.7/site-packages/sqlalchemy/orm/query.py", line 2765, in _connection_from_session, referer: http://192.168.0.6:505/
[Wed Jun 08 16:47:31.638613 2016] [wsgi:error] [pid 946] [client 192.168.0.6:55599]     **kw), referer: http://192.168.0.6:505/
[Wed Jun 08 16:47:31.638627 2016] [wsgi:error] [pid 946] [client 192.168.0.6:55599]   File "/Users/jinho/Citadel/venv/lib/python2.7/site-packages/sqlalchemy/orm/session.py", line 893, in connection, referer: http://192.168.0.6:505/
[Wed Jun 08 16:47:31.638661 2016] [wsgi:error] [pid 946] [client 192.168.0.6:55599]     execution_options=execution_options), referer: http://192.168.0.6:505/
[Wed Jun 08 16:47:31.638676 2016] [wsgi:error] [pid 946] [client 192.168.0.6:55599]   File "/Users/jinho/Citadel/venv/lib/python2.7/site-packages/sqlalchemy/orm/session.py", line 898, in _connection_for_bind, referer: http://192.168.0.6:505/
[Wed Jun 08 16:47:31.638703 2016] [wsgi:error] [pid 946] [client 192.168.0.6:55599]     engine, execution_options), referer: http://192.168.0.6:505/
[Wed Jun 08 16:47:31.638717 2016] [wsgi:error] [pid 946] [client 192.168.0.6:55599]   File "/Users/jinho/Citadel/venv/lib/python2.7/site-packages/sqlalchemy/orm/session.py", line 313, in _connection_for_bind, referer: http://192.168.0.6:505/
[Wed Jun 08 16:47:31.638743 2016] [wsgi:error] [pid 946] [client 192.168.0.6:55599]     self._assert_active(), referer: http://192.168.0.6:505/
[Wed Jun 08 16:47:31.638779 2016] [wsgi:error] [pid 946] [client 192.168.0.6:55599]   File "/Users/jinho/Citadel/venv/lib/python2.7/site-packages/sqlalchemy/orm/session.py", line 214, in _assert_active, referer: http://192.168.0.6:505/
[Wed Jun 08 16:47:31.638811 2016] [wsgi:error] [pid 946] [client 192.168.0.6:55599]     % self._rollback_exception, referer: http://192.168.0.6:505/
[Wed Jun 08 16:47:31.638847 2016] [wsgi:error] [pid 946] [client 192.168.0.6:55599] InvalidRequestError: This Session's transaction has been rolled back due to a previous exception during flush. To begin a new transaction with this Session, first issue Session.rollback(). Original exception was: (sqlite3.OperationalError) unable to open database file [SQL: u'UPDATE message SET title=? WHERE message.id = ?'] [parameters: (u'4$\\uc544\\uc624 \\uc9c4\\uc9dc \\uc9dc\\uc99d\\ub098\\ub290\\uad6c\\ub9cc', 10)], referer: http://192.168.0.6:505/
